Workbook

Sheet Control Groups
A1: Control ID | B1: Control Description | C1: Control Group / Tier | D1: Benchmark Basis
A2: AC-01 | B2: Default local accounts disabled | C2: Tier 0 – Universal | D2: CIS OS Benchmark
A3: AC-02 | B3: Privileged access restricted | C3: Tier 0 – Universal | D3: CIS Control 5
A4: AC-03 | B4: MFA enabled where supported | C4: Tier 1 – Trust / Control Plane | D4: CIS Control 6
A5: AC-04 | B5: Automatic screen lock enforced | C5: Tier 2 – Exposure | D5: CIS OS Benchmark
A6: SH-01 | B6: Secure baseline applied | C6: Tier 0 – Universal | D6: CIS OS Benchmark
A7: SH-02 | B7: Unnecessary services removed | C7: Tier 2 – Exposure | D7: CIS OS Benchmark
A8: SH-03 | B8: Disk encryption enabled | C8: Tier 3 – Data | D8: CIS Data Protection
A9: NS-01 | B9: Host firewall enabled | C9: Tier 1 – Trust / Control Plane | D9: CIS Control 4
A10: NS-02 | B10: Inbound traffic restricted | C10: Tier 2 – Exposure | D10: CIS Control 4
A11: NS-03 | B11: Management access restricted | C11: Tier 1 – Trust / Control Plane | D11: CIS Control 4
A12: LM-01 | B12: System logging enabled | C12: Tier 0 – Universal | D12: CIS Control 8
... A27: SOP-09 | B27: Configuration changes documented | C27: Tier 0 – Universal | D27: NIST CM

Sheet Mandatory Controls Matrix
A1: Control ID | B1: Control Description | C1: INF-01 Hypervisor | D1: INF-02 Storage | E1: INF-03 Backup Infra | F1: INF-04 Network Infra | G1: INF-05 Physical Host | H1: CORE-01 Identity | I1: CORE-02 DNS/DHCP/NTP | J1: CORE-03 PKI | K1: CORE-04 Auth Proxy | L1: APP-01 App Server | M1: APP-02 Web Server | N1: APP-03 Runtime | O1: APP-04 API | P1: APP-05 Batch | Q1: DATA-01 Database | R1: DATA-02 File Server | S1: DATA-03 BI | T1: DATA-04 ETL | U1: SEC-01 SIEM | V1: SEC-02 Sec Mgmt | W1: SEC-03 Bastion
A2: Category Code | C2: INF-01 | D2: INF-02 | E2: INF-03 | F2: INF-04 | G2: INF-05 | H2: CORE-01 | I2: CORE-02 | J2: CORE-03 | K2: CORE-04 | L2: APP-01 | M2: APP-02 | N2: APP-03 | O2: APP-04 | P2: APP-05 | Q2: DATA-01 | R2: DATA-02 | S2: DATA-03 | T2: DATA-04 | U2: SEC-01 | V2: SEC-02 | W2: SEC-03
A3: AC-01 | B3: Default local accounts disabled | C3: =IF(VLOOKUP($A3,'Control Groups'!$A:$D,3,FALSE)="Tier 0 – Universal","Yes",IF(COUNTIFS('Tier Category Mapping'!$A:$A,VLOOKUP($A3,'Control Groups'!$A:$D,3,FALSE),'Tier Category Mapping'!$B:$B,C2,'Tier Category Mapping'!$D:$D,"Yes")>0,"Yes","")) | D3: =IF(VLOOKUP($A3,'Control Groups'!$A:$D,3,FALSE)="Tier 0 – Universal","Yes",IF(COUNTIFS('Tier Category Mapping'!$A:$A,VLOOKUP($A3,'Control Groups'!$A:$D,3,FALSE),'Tier Category Mapping'!$B:$B,D2,'Tier Category Mapping'!$D:$D,"Yes")>0,"Yes","")) | E3: =IF(VLOOKUP($A3,'Control Groups'!$A:$D,3,FALSE)="Tier 0 – Universal","Yes",IF(COUNTIFS('Tier Category Mapping'!$A:$A,VLOOKUP($A3,'Control Groups'!$A:$D,3,FALSE),'Tier Category Mapping'!$B:$B,E2,'Tier Category Mapping'!$D:$D,"Yes")>0,"Yes","")) | F3: =IF(VLOOKUP($A3,'Control Groups'!$A:$D,3,FALSE)="Tier 0 – Universal","Yes",IF(COUNTIFS('Tier Category Mapping'!$A:$A,VLOOKUP($A3,'Control Groups'!$A:$D,3,FALSE),'Tier Category Mapping'!$B:$B,F2,'Tier Category Mapping'!$D:$D,"Yes")>0,"Yes","")) | G3: =IF(VLOOKUP($A3,'Control Groups'!$A:$D,3,FALSE)="Tier 0 – Universal","Yes",IF(COUNTIFS('Tier Category Mapping'!$A:$A,VLOOKUP($A3,'Control Groups'!$A:$D,3,FALSE),'Tier Category Mapping'!$B:$B,G2,'Tier Category Mapping'!$D:$D,"Yes")>0,"Yes","")) | H3: =IF(VLOOKUP($A3,'Control Groups'!$A:$D,3,FALSE)="Tier 0 – Universal","Yes",IF(COUNTIFS('Tier Category Mapping'!$A:$A,VLOOKUP($A3,'Control Groups'!$A:$D,3,FALSE),'Tier Category Mapping'!$B:$B,H2,'Tier Category Mapping'!$D:$D,"Yes")>0,"Yes","")) | I3: =IF(VLOOKUP($A3,'Control Groups'!$A:$D,3,FALSE)="Tier 0 – Universal","Yes",IF(COUNTIFS('Tier Category Mapping'!$A:$A,VLOOKUP($A3,'Control Groups'!$A:$D,3,FALSE),'Tier Category Mapping'!$B:$B,I2,'Tier Category Mapping'!$D:$D,"Yes")>0,"Yes","")) | J3: =IF(VLOOKUP($A3,'Control Groups'!$A:$D,3,FALSE)="Tier 0 – Universal","Yes",IF(COUNTIFS('Tier Category Mapping'!$A:$A,VLOOKUP($A3,'Control Groups'!$A:$D,3,FALSE),'Tier Category Mapping'!$B:$B,J2,'Tier Category Mapping'!$D:$D,"Yes")>0,"Yes","")) | ... W3: =IF(VLOOKUP($A3,'Control Groups'!$A:$D,3,FALSE)="Tier 0 – Universal","Yes",IF(COUNTIFS('Tier Category Mapping'!$A:$A,VLOOKUP($A3,'Control Groups'!$A:$D,3,FALSE),'Tier Category Mapping'!$B:$B,W2,'Tier Category Mapping'!$D:$D,"Yes")>0,"Yes",""))
A4: AC-02 | B4: Privileged access restricted | C4: =IF(VLOOKUP($A4,'Control Groups'!$A:$D,3,FALSE)="Tier 0 – Universal","Yes",IF(COUNTIFS('Tier Category Mapping'!$A:$A,VLOOKUP($A4,'Control Groups'!$A:$D,3,FALSE),'Tier Category Mapping'!$B:$B,C2,'Tier Category Mapping'!$D:$D,"Yes")>0,"Yes","")) | D4: =IF(VLOOKUP($A4,'Control Groups'!$A:$D,3,FALSE)="Tier 0 – Universal","Yes",IF(COUNTIFS('Tier Category Mapping'!$A:$A,VLOOKUP($A4,'Control Groups'!$A:$D,3,FALSE),'Tier Category Mapping'!$B:$B,D2,'Tier Category Mapping'!$D:$D,"Yes")>0,"Yes","")) | E4: =IF(VLOOKUP($A4,'Control Groups'!$A:$D,3,FALSE)="Tier 0 – Universal","Yes",IF(COUNTIFS('Tier Category Mapping'!$A:$A,VLOOKUP($A4,'Control Groups'!$A:$D,3,FALSE),'Tier Category Mapping'!$B:$B,E2,'Tier Category Mapping'!$D:$D,"Yes")>0,"Yes","")) | F4: =IF(VLOOKUP($A4,'Control Groups'!$A:$D,3,FALSE)="Tier 0 – Universal","Yes",IF(COUNTIFS('Tier Category Mapping'!$A:$A,VLOOKUP($A4,'Control Groups'!$A:$D,3,FALSE),'Tier Category Mapping'!$B:$B,F2,'Tier Category Mapping'!$D:$D,"Yes")>0,"Yes","")) | G4: =IF(VLOOKUP($A4,'Control Groups'!$A:$D,3,FALSE)="Tier 0 – Universal","Yes",IF(COUNTIFS('Tier Category Mapping'!$A:$A,VLOOKUP($A4,'Control Groups'!$A:$D,3,FALSE),'Tier Category Mapping'!$B:$B,G2,'Tier Category Mapping'!$D:$D,"Yes")>0,"Yes","")) | H4: =IF(VLOOKUP($A4,'Control Groups'!$A:$D,3,FALSE)="Tier 0 – Universal","Yes",IF(COUNTIFS('Tier Category Mapping'!$A:$A,VLOOKUP($A4,'Control Groups'!$A:$D,3,FALSE),'Tier Category Mapping'!$B:$B,H2,'Tier Category Mapping'!$D:$D,"Yes")>0,"Yes","")) | I4: =IF(VLOOKUP($A4,'Control Groups'!$A:$D,3,FALSE)="Tier 0 – Universal","Yes",IF(COUNTIFS('Tier Category Mapping'!$A:$A,VLOOKUP($A4,'Control Groups'!$A:$D,3,FALSE),'Tier Category Mapping'!$B:$B,I2,'Tier Category Mapping'!$D:$D,"Yes")>0,"Yes","")) | J4: =IF(VLOOKUP($A4,'Control Groups'!$A:$D,3,FALSE)="Tier 0 – Universal","Yes",IF(COUNTIFS('Tier Category Mapping'!$A:$A,VLOOKUP($A4,'Control Groups'!$A:$D,3,FALSE),'Tier Category Mapping'!$B:$B,J2,'Tier Category Mapping'!$D:$D,"Yes")>0,"Yes","")) | ... W4: =IF(VLOOKUP($A4,'Control Groups'!$A:$D,3,FALSE)="Tier 0 – Universal","Yes",IF(COUNTIFS('Tier Category Mapping'!$A:$A,VLOOKUP($A4,'Control Groups'!$A:$D,3,FALSE),'Tier Category Mapping'!$B:$B,W2,'Tier Category Mapping'!$D:$D,"Yes")>0,"Yes",""))
A5: AC-03 | B5: MFA enabled where supported | C5: =IF(VLOOKUP($A5,'Control Groups'!$A:$D,3,FALSE)="Tier 0 – Universal","Yes",IF(COUNTIFS('Tier Category Mapping'!$A:$A,VLOOKUP($A5,'Control Groups'!$A:$D,3,FALSE),'Tier Category Mapping'!$B:$B,C2,'Tier Category Mapping'!$D:$D,"Yes")>0,"Yes","")) | D5: =IF(VLOOKUP($A5,'Control Groups'!$A:$D,3,FALSE)="Tier 0 – Universal","Yes",IF(COUNTIFS('Tier Category Mapping'!$A:$A,VLOOKUP($A5,'Control Groups'!$A:$D,3,FALSE),'Tier Category Mapping'!$B:$B,D2,'Tier Category Mapping'!$D:$D,"Yes")>0,"Yes","")) | E5: =IF(VLOOKUP($A5,'Control Groups'!$A:$D,3,FALSE)="Tier 0 – Universal","Yes",IF(COUNTIFS('Tier Category Mapping'!$A:$A,VLOOKUP($A5,'Control Groups'!$A:$D,3,FALSE),'Tier Category Mapping'!$B:$B,E2,'Tier Category Mapping'!$D:$D,"Yes")>0,"Yes","")) | F5: =IF(VLOOKUP($A5,'Control Groups'!$A:$D,3,FALSE)="Tier 0 – Universal","Yes",IF(COUNTIFS('Tier Category Mapping'!$A:$A,VLOOKUP($A5,'Control Groups'!$A:$D,3,FALSE),'Tier Category Mapping'!$B:$B,F2,'Tier Category Mapping'!$D:$D,"Yes")>0,"Yes","")) | G5: =IF(VLOOKUP($A5,'Control Groups'!$A:$D,3,FALSE)="Tier 0 – Universal","Yes",IF(COUNTIFS('Tier Category Mapping'!$A:$A,VLOOKUP($A5,'Control Groups'!$A:$D,3,FALSE),'Tier Category Mapping'!$B:$B,G2,'Tier Category Mapping'!$D:$D,"Yes")>0,"Yes","")) | H5: =IF(VLOOKUP($A5,'Control Groups'!$A:$D,3,FALSE)="Tier 0 – Universal","Yes",IF(COUNTIFS('Tier Category Mapping'!$A:$A,VLOOKUP($A5,'Control Groups'!$A:$D,3,FALSE),'Tier Category Mapping'!$B:$B,H2,'Tier Category Mapping'!$D:$D,"Yes")>0,"Yes","")) | I5: =IF(VLOOKUP($A5,'Control Groups'!$A:$D,3,FALSE)="Tier 0 – Universal","Yes",IF(COUNTIFS('Tier Category Mapping'!$A:$A,VLOOKUP($A5,'Control Groups'!$A:$D,3,FALSE),'Tier Category Mapping'!$B:$B,I2,'Tier Category Mapping'!$D:$D,"Yes")>0,"Yes","")) | J5: =IF(VLOOKUP($A5,'Control Groups'!$A:$D,3,FALSE)="Tier 0 – Universal","Yes",IF(COUNTIFS('Tier Category Mapping'!$A:$A,VLOOKUP($A5,'Control Groups'!$A:$D,3,FALSE),'Tier Category Mapping'!$B:$B,J2,'Tier Category Mapping'!$D:$D,"Yes")>0,"Yes","")) | ... W5: =IF(VLOOKUP($A5,'Control Groups'!$A:$D,3,FALSE)="Tier 0 – Universal","Yes",IF(COUNTIFS('Tier Category Mapping'!$A:$A,VLOOKUP($A5,'Control Groups'!$A:$D,3,FALSE),'Tier Category Mapping'!$B:$B,W2,'Tier Category Mapping'!$D:$D,"Yes")>0,"Yes",""))
A6: AC-04 | B6: Automatic screen lock enforced | C6: =IF(VLOOKUP($A6,'Control Groups'!$A:$D,3,FALSE)="Tier 0 – Universal","Yes",IF(COUNTIFS('Tier Category Mapping'!$A:$A,VLOOKUP($A6,'Control Groups'!$A:$D,3,FALSE),'Tier Category Mapping'!$B:$B,C2,'Tier Category Mapping'!$D:$D,"Yes")>0,"Yes","")) | D6: =IF(VLOOKUP($A6,'Control Groups'!$A:$D,3,FALSE)="Tier 0 – Universal","Yes",IF(COUNTIFS('Tier Category Mapping'!$A:$A,VLOOKUP($A6,'Control Groups'!$A:$D,3,FALSE),'Tier Category Mapping'!$B:$B,D2,'Tier Category Mapping'!$D:$D,"Yes")>0,"Yes","")) | E6: =IF(VLOOKUP($A6,'Control Groups'!$A:$D,3,FALSE)="Tier 0 – Universal","Yes",IF(COUNTIFS('Tier Category Mapping'!$A:$A,VLOOKUP($A6,'Control Groups'!$A:$D,3,FALSE),'Tier Category Mapping'!$B:$B,E2,'Tier Category Mapping'!$D:$D,"Yes")>0,"Yes","")) | F6: =IF(VLOOKUP($A6,'Control Groups'!$A:$D,3,FALSE)="Tier 0 – Universal","Yes",IF(COUNTIFS('Tier Category Mapping'!$A:$A,VLOOKUP($A6,'Control Groups'!$A:$D,3,FALSE),'Tier Category Mapping'!$B:$B,F2,'Tier Category Mapping'!$D:$D,"Yes")>0,"Yes","")) | G6: =IF(VLOOKUP($A6,'Control Groups'!$A:$D,3,FALSE)="Tier 0 – Universal","Yes",IF(COUNTIFS('Tier Category Mapping'!$A:$A,VLOOKUP($A6,'Control Groups'!$A:$D,3,FALSE),'Tier Category Mapping'!$B:$B,G2,'Tier Category Mapping'!$D:$D,"Yes")>0,"Yes","")) | H6: =IF(VLOOKUP($A6,'Control Groups'!$A:$D,3,FALSE)="Tier 0 – Universal","Yes",IF(COUNTIFS('Tier Category Mapping'!$A:$A,VLOOKUP($A6,'Control Groups'!$A:$D,3,FALSE),'Tier Category Mapping'!$B:$B,H2,'Tier Category Mapping'!$D:$D,"Yes")>0,"Yes","")) | I6: =IF(VLOOKUP($A6,'Control Groups'!$A:$D,3,FALSE)="Tier 0 – Universal","Yes",IF(COUNTIFS('Tier Category Mapping'!$A:$A,VLOOKUP($A6,'Control Groups'!$A:$D,3,FALSE),'Tier Category Mapping'!$B:$B,I2,'Tier Category Mapping'!$D:$D,"Yes")>0,"Yes","")) | J6: =IF(VLOOKUP($A6,'Control Groups'!$A:$D,3,FALSE)="Tier 0 – Universal","Yes",IF(COUNTIFS('Tier Category Mapping'!$A:$A,VLOOKUP($A6,'Control Groups'!$A:$D,3,FALSE),'Tier Category Mapping'!$B:$B,J2,'Tier Category Mapping'!$D:$D,"Yes")>0,"Yes","")) | ... W6: =IF(VLOOKUP($A6,'Control Groups'!$A:$D,3,FALSE)="Tier 0 – Universal","Yes",IF(COUNTIFS('Tier Category Mapping'!$A:$A,VLOOKUP($A6,'Control Groups'!$A:$D,3,FALSE),'Tier Category Mapping'!$B:$B,W2,'Tier Category Mapping'!$D:$D,"Yes")>0,"Yes",""))
A7: SH-01 | B7: Secure baseline applied | C7: =IF(VLOOKUP($A7,'Control Groups'!$A:$D,3,FALSE)="Tier 0 – Universal","Yes",IF(COUNTIFS('Tier Category Mapping'!$A:$A,VLOOKUP($A7,'Control Groups'!$A:$D,3,FALSE),'Tier Category Mapping'!$B:$B,C2,'Tier Category Mapping'!$D:$D,"Yes")>0,"Yes","")) | D7: =IF(VLOOKUP($A7,'Control Groups'!$A:$D,3,FALSE)="Tier 0 – Universal","Yes",IF(COUNTIFS('Tier Category Mapping'!$A:$A,VLOOKUP($A7,'Control Groups'!$A:$D,3,FALSE),'Tier Category Mapping'!$B:$B,D2,'Tier Category Mapping'!$D:$D,"Yes")>0,"Yes","")) | E7: =IF(VLOOKUP($A7,'Control Groups'!$A:$D,3,FALSE)="Tier 0 – Universal","Yes",IF(COUNTIFS('Tier Category Mapping'!$A:$A,VLOOKUP($A7,'Control Groups'!$A:$D,3,FALSE),'Tier Category Mapping'!$B:$B,E2,'Tier Category Mapping'!$D:$D,"Yes")>0,"Yes","")) | F7: =IF(VLOOKUP($A7,'Control Groups'!$A:$D,3,FALSE)="Tier 0 – Universal","Yes",IF(COUNTIFS('Tier Category Mapping'!$A:$A,VLOOKUP($A7,'Control Groups'!$A:$D,3,FALSE),'Tier Category Mapping'!$B:$B,F2,'Tier Category Mapping'!$D:$D,"Yes")>0,"Yes","")) | G7: =IF(VLOOKUP($A7,'Control Groups'!$A:$D,3,FALSE)="Tier 0 – Universal","Yes",IF(COUNTIFS('Tier Category Mapping'!$A:$A,VLOOKUP($A7,'Control Groups'!$A:$D,3,FALSE),'Tier Category Mapping'!$B:$B,G2,'Tier Category Mapping'!$D:$D,"Yes")>0,"Yes","")) | H7: =IF(VLOOKUP($A7,'Control Groups'!$A:$D,3,FALSE)="Tier 0 – Universal","Yes",IF(COUNTIFS('Tier Category Mapping'!$A:$A,VLOOKUP($A7,'Control Groups'!$A:$D,3,FALSE),'Tier Category Mapping'!$B:$B,H2,'Tier Category Mapping'!$D:$D,"Yes")>0,"Yes","")) | I7: =IF(VLOOKUP($A7,'Control Groups'!$A:$D,3,FALSE)="Tier 0 – Universal","Yes",IF(COUNTIFS('Tier Category Mapping'!$A:$A,VLOOKUP($A7,'Control Groups'!$A:$D,3,FALSE),'Tier Category Mapping'!$B:$B,I2,'Tier Category Mapping'!$D:$D,"Yes")>0,"Yes","")) | J7: =IF(VLOOKUP($A7,'Control Groups'!$A:$D,3,FALSE)="Tier 0 – Universal","Yes",IF(COUNTIFS('Tier Category Mapping'!$A:$A,VLOOKUP($A7,'Control Groups'!$A:$D,3,FALSE),'Tier Category Mapping'!$B:$B,J2,'Tier Category Mapping'!$D:$D,"Yes")>0,"Yes","")) | ... W7: =IF(VLOOKUP($A7,'Control Groups'!$A:$D,3,FALSE)="Tier 0 – Universal","Yes",IF(COUNTIFS('Tier Category Mapping'!$A:$A,VLOOKUP($A7,'Control Groups'!$A:$D,3,FALSE),'Tier Category Mapping'!$B:$B,W2,'Tier Category Mapping'!$D:$D,"Yes")>0,"Yes",""))
A8: SH-02 | B8: Unnecessary services removed | C8: =IF(VLOOKUP($A8,'Control Groups'!$A:$D,3,FALSE)="Tier 0 – Universal","Yes",IF(COUNTIFS('Tier Category Mapping'!$A:$A,VLOOKUP($A8,'Control Groups'!$A:$D,3,FALSE),'Tier Category Mapping'!$B:$B,C2,'Tier Category Mapping'!$D:$D,"Yes")>0,"Yes","")) | D8: =IF(VLOOKUP($A8,'Control Groups'!$A:$D,3,FALSE)="Tier 0 – Universal","Yes",IF(COUNTIFS('Tier Category Mapping'!$A:$A,VLOOKUP($A8,'Control Groups'!$A:$D,3,FALSE),'Tier Category Mapping'!$B:$B,D2,'Tier Category Mapping'!$D:$D,"Yes")>0,"Yes","")) | E8: =IF(VLOOKUP($A8,'Control Groups'!$A:$D,3,FALSE)="Tier 0 – Universal","Yes",IF(COUNTIFS('Tier Category Mapping'!$A:$A,VLOOKUP($A8,'Control Groups'!$A:$D,3,FALSE),'Tier Category Mapping'!$B:$B,E2,'Tier Category Mapping'!$D:$D,"Yes")>0,"Yes","")) | F8: =IF(VLOOKUP($A8,'Control Groups'!$A:$D,3,FALSE)="Tier 0 – Universal","Yes",IF(COUNTIFS('Tier Category Mapping'!$A:$A,VLOOKUP($A8,'Control Groups'!$A:$D,3,FALSE),'Tier Category Mapping'!$B:$B,F2,'Tier Category Mapping'!$D:$D,"Yes")>0,"Yes","")) | G8: =IF(VLOOKUP($A8,'Control Groups'!$A:$D,3,FALSE)="Tier 0 – Universal","Yes",IF(COUNTIFS('Tier Category Mapping'!$A:$A,VLOOKUP($A8,'Control Groups'!$A:$D,3,FALSE),'Tier Category Mapping'!$B:$B,G2,'Tier Category Mapping'!$D:$D,"Yes")>0,"Yes","")) | H8: =IF(VLOOKUP($A8,'Control Groups'!$A:$D,3,FALSE)="Tier 0 – Universal","Yes",IF(COUNTIFS('Tier Category Mapping'!$A:$A,VLOOKUP($A8,'Control Groups'!$A:$D,3,FALSE),'Tier Category Mapping'!$B:$B,H2,'Tier Category Mapping'!$D:$D,"Yes")>0,"Yes","")) | I8: =IF(VLOOKUP($A8,'Control Groups'!$A:$D,3,FALSE)="Tier 0 – Universal","Yes",IF(COUNTIFS('Tier Category Mapping'!$A:$A,VLOOKUP($A8,'Control Groups'!$A:$D,3,FALSE),'Tier Category Mapping'!$B:$B,I2,'Tier Category Mapping'!$D:$D,"Yes")>0,"Yes","")) | J8: =IF(VLOOKUP($A8,'Control Groups'!$A:$D,3,FALSE)="Tier 0 – Universal","Yes",IF(COUNTIFS('Tier Category Mapping'!$A:$A,VLOOKUP($A8,'Control Groups'!$A:$D,3,FALSE),'Tier Category Mapping'!$B:$B,J2,'Tier Category Mapping'!$D:$D,"Yes")>0,"Yes","")) | ... W8: =IF(VLOOKUP($A8,'Control Groups'!$A:$D,3,FALSE)="Tier 0 – Universal","Yes",IF(COUNTIFS('Tier Category Mapping'!$A:$A,VLOOKUP($A8,'Control Groups'!$A:$D,3,FALSE),'Tier Category Mapping'!$B:$B,W2,'Tier Category Mapping'!$D:$D,"Yes")>0,"Yes",""))
A9: SH-03 | B9: Disk encryption enabled | C9: =IF(VLOOKUP($A9,'Control Groups'!$A:$D,3,FALSE)="Tier 0 – Universal","Yes",IF(COUNTIFS('Tier Category Mapping'!$A:$A,VLOOKUP($A9,'Control Groups'!$A:$D,3,FALSE),'Tier Category Mapping'!$B:$B,C2,'Tier Category Mapping'!$D:$D,"Yes")>0,"Yes","")) | D9: =IF(VLOOKUP($A9,'Control Groups'!$A:$D,3,FALSE)="Tier 0 – Universal","Yes",IF(COUNTIFS('Tier Category Mapping'!$A:$A,VLOOKUP($A9,'Control Groups'!$A:$D,3,FALSE),'Tier Category Mapping'!$B:$B,D2,'Tier Category Mapping'!$D:$D,"Yes")>0,"Yes","")) | E9: =IF(VLOOKUP($A9,'Control Groups'!$A:$D,3,FALSE)="Tier 0 – Universal","Yes",IF(COUNTIFS('Tier Category Mapping'!$A:$A,VLOOKUP($A9,'Control Groups'!$A:$D,3,FALSE),'Tier Category Mapping'!$B:$B,E2,'Tier Category Mapping'!$D:$D,"Yes")>0,"Yes","")) | F9: =IF(VLOOKUP($A9,'Control Groups'!$A:$D,3,FALSE)="Tier 0 – Universal","Yes",IF(COUNTIFS('Tier Category Mapping'!$A:$A,VLOOKUP($A9,'Control Groups'!$A:$D,3,FALSE),'Tier Category Mapping'!$B:$B,F2,'Tier Category Mapping'!$D:$D,"Yes")>0,"Yes","")) | G9: =IF(VLOOKUP($A9,'Control Groups'!$A:$D,3,FALSE)="Tier 0 – Universal","Yes",IF(COUNTIFS('Tier Category Mapping'!$A:$A,VLOOKUP($A9,'Control Groups'!$A:$D,3,FALSE),'Tier Category Mapping'!$B:$B,G2,'Tier Category Mapping'!$D:$D,"Yes")>0,"Yes","")) | H9: =IF(VLOOKUP($A9,'Control Groups'!$A:$D,3,FALSE)="Tier 0 – Universal","Yes",IF(COUNTIFS('Tier Category Mapping'!$A:$A,VLOOKUP($A9,'Control Groups'!$A:$D,3,FALSE),'Tier Category Mapping'!$B:$B,H2,'Tier Category Mapping'!$D:$D,"Yes")>0,"Yes","")) | I9: =IF(VLOOKUP($A9,'Control Groups'!$A:$D,3,FALSE)="Tier 0 – Universal","Yes",IF(COUNTIFS('Tier Category Mapping'!$A:$A,VLOOKUP($A9,'Control Groups'!$A:$D,3,FALSE),'Tier Category Mapping'!$B:$B,I2,'Tier Category Mapping'!$D:$D,"Yes")>0,"Yes","")) | J9: =IF(VLOOKUP($A9,'Control Groups'!$A:$D,3,FALSE)="Tier 0 – Universal","Yes",IF(COUNTIFS('Tier Category Mapping'!$A:$A,VLOOKUP($A9,'Control Groups'!$A:$D,3,FALSE),'Tier Category Mapping'!$B:$B,J2,'Tier Category Mapping'!$D:$D,"Yes")>0,"Yes","")) | ... W9: =IF(VLOOKUP($A9,'Control Groups'!$A:$D,3,FALSE)="Tier 0 – Universal","Yes",IF(COUNTIFS('Tier Category Mapping'!$A:$A,VLOOKUP($A9,'Control Groups'!$A:$D,3,FALSE),'Tier Category Mapping'!$B:$B,W2,'Tier Category Mapping'!$D:$D,"Yes")>0,"Yes",""))
A10: NS-01 | B10: Host firewall enabled | C10: =IF(VLOOKUP($A10,'Control Groups'!$A:$D,3,FALSE)="Tier 0 – Universal","Yes",IF(COUNTIFS('Tier Category Mapping'!$A:$A,VLOOKUP($A10,'Control Groups'!$A:$D,3,FALSE),'Tier Category Mapping'!$B:$B,C2,'Tier Category Mapping'!$D:$D,"Yes")>0,"Yes","")) | D10: =IF(VLOOKUP($A10,'Control Groups'!$A:$D,3,FALSE)="Tier 0 – Universal","Yes",IF(COUNTIFS('Tier Category Mapping'!$A:$A,VLOOKUP($A10,'Control Groups'!$A:$D,3,FALSE),'Tier Category Mapping'!$B:$B,D2,'Tier Category Mapping'!$D:$D,"Yes")>0,"Yes","")) | E10: =IF(VLOOKUP($A10,'Control Groups'!$A:$D,3,FALSE)="Tier 0 – Universal","Yes",IF(COUNTIFS('Tier Category Mapping'!$A:$A,VLOOKUP($A10,'Control Groups'!$A:$D,3,FALSE),'Tier Category Mapping'!$B:$B,E2,'Tier Category Mapping'!$D:$D,"Yes")>0,"Yes","")) | F10: =IF(VLOOKUP($A10,'Control Groups'!$A:$D,3,FALSE)="Tier 0 – Universal","Yes",IF(COUNTIFS('Tier Category Mapping'!$A:$A,VLOOKUP($A10,'Control Groups'!$A:$D,3,FALSE),'Tier Category Mapping'!$B:$B,F2,'Tier Category Mapping'!$D:$D,"Yes")>0,"Yes","")) | G10: =IF(VLOOKUP($A10,'Control Groups'!$A:$D,3,FALSE)="Tier 0 – Universal","Yes",IF(COUNTIFS('Tier Category Mapping'!$A:$A,VLOOKUP($A10,'Control Groups'!$A:$D,3,FALSE),'Tier Category Mapping'!$B:$B,G2,'Tier Category Mapping'!$D:$D,"Yes")>0,"Yes","")) | H10: =IF(VLOOKUP($A10,'Control Groups'!$A:$D,3,FALSE)="Tier 0 – Universal","Yes",IF(COUNTIFS('Tier Category Mapping'!$A:$A,VLOOKUP($A10,'Control Groups'!$A:$D,3,FALSE),'Tier Category Mapping'!$B:$B,H2,'Tier Category Mapping'!$D:$D,"Yes")>0,"Yes","")) | I10: =IF(VLOOKUP($A10,'Control Groups'!$A:$D,3,FALSE)="Tier 0 – Universal","Yes",IF(COUNTIFS('Tier Category Mapping'!$A:$A,VLOOKUP($A10,'Control Groups'!$A:$D,3,FALSE),'Tier Category Mapping'!$B:$B,I2,'Tier Category Mapping'!$D:$D,"Yes")>0,"Yes","")) | J10: =IF(VLOOKUP($A10,'Control Groups'!$A:$D,3,FALSE)="Tier 0 – Universal","Yes",IF(COUNTIFS('Tier Category Mapping'!$A:$A,VLOOKUP($A10,'Control Groups'!$A:$D,3,FALSE),'Tier Category Mapping'!$B:$B,J2,'Tier Category Mapping'!$D:$D,"Yes")>0,"Yes","")) | ... W10: =IF(VLOOKUP($A10,'Control Groups'!$A:$D,3,FALSE)="Tier 0 – Universal","Yes",IF(COUNTIFS('Tier Category Mapping'!$A:$A,VLOOKUP($A10,'Control Groups'!$A:$D,3,FALSE),'Tier Category Mapping'!$B:$B,W2,'Tier Category Mapping'!$D:$D,"Yes")>0,"Yes",""))
A11: NS-02 | B11: Inbound traffic restricted | C11: =IF(VLOOKUP($A11,'Control Groups'!$A:$D,3,FALSE)="Tier 0 – Universal","Yes",IF(COUNTIFS('Tier Category Mapping'!$A:$A,VLOOKUP($A11,'Control Groups'!$A:$D,3,FALSE),'Tier Category Mapping'!$B:$B,C2,'Tier Category Mapping'!$D:$D,"Yes")>0,"Yes","")) | D11: =IF(VLOOKUP($A11,'Control Groups'!$A:$D,3,FALSE)="Tier 0 – Universal","Yes",IF(COUNTIFS('Tier Category Mapping'!$A:$A,VLOOKUP($A11,'Control Groups'!$A:$D,3,FALSE),'Tier Category Mapping'!$B:$B,D2,'Tier Category Mapping'!$D:$D,"Yes")>0,"Yes","")) | E11: =IF(VLOOKUP($A11,'Control Groups'!$A:$D,3,FALSE)="Tier 0 – Universal","Yes",IF(COUNTIFS('Tier Category Mapping'!$A:$A,VLOOKUP($A11,'Control Groups'!$A:$D,3,FALSE),'Tier Category Mapping'!$B:$B,E2,'Tier Category Mapping'!$D:$D,"Yes")>0,"Yes","")) | F11: =IF(VLOOKUP($A11,'Control Groups'!$A:$D,3,FALSE)="Tier 0 – Universal","Yes",IF(COUNTIFS('Tier Category Mapping'!$A:$A,VLOOKUP($A11,'Control Groups'!$A:$D,3,FALSE),'Tier Category Mapping'!$B:$B,F2,'Tier Category Mapping'!$D:$D,"Yes")>0,"Yes","")) | G11: =IF(VLOOKUP($A11,'Control Groups'!$A:$D,3,FALSE)="Tier 0 – Universal","Yes",IF(COUNTIFS('Tier Category Mapping'!$A:$A,VLOOKUP($A11,'Control Groups'!$A:$D,3,FALSE),'Tier Category Mapping'!$B:$B,G2,'Tier Category Mapping'!$D:$D,"Yes")>0,"Yes","")) | H11: =IF(VLOOKUP($A11,'Control Groups'!$A:$D,3,FALSE)="Tier 0 – Universal","Yes",IF(COUNTIFS('Tier Category Mapping'!$A:$A,VLOOKUP($A11,'Control Groups'!$A:$D,3,FALSE),'Tier Category Mapping'!$B:$B,H2,'Tier Category Mapping'!$D:$D,"Yes")>0,"Yes","")) | I11: =IF(VLOOKUP($A11,'Control Groups'!$A:$D,3,FALSE)="Tier 0 – Universal","Yes",IF(COUNTIFS('Tier Category Mapping'!$A:$A,VLOOKUP($A11,'Control Groups'!$A:$D,3,FALSE),'Tier Category Mapping'!$B:$B,I2,'Tier Category Mapping'!$D:$D,"Yes")>0,"Yes","")) | J11: =IF(VLOOKUP($A11,'Control Groups'!$A:$D,3,FALSE)="Tier 0 – Universal","Yes",IF(COUNTIFS('Tier Category Mapping'!$A:$A,VLOOKUP($A11,'Control Groups'!$A:$D,3,FALSE),'Tier Category Mapping'!$B:$B,J2,'Tier Category Mapping'!$D:$D,"Yes")>0,"Yes","")) | ... W11: =IF(VLOOKUP($A11,'Control Groups'!$A:$D,3,FALSE)="Tier 0 – Universal","Yes",IF(COUNTIFS('Tier Category Mapping'!$A:$A,VLOOKUP($A11,'Control Groups'!$A:$D,3,FALSE),'Tier Category Mapping'!$B:$B,W2,'Tier Category Mapping'!$D:$D,"Yes")>0,"Yes",""))
A12: NS-03 | B12: Management access restricted | C12: =IF(VLOOKUP($A12,'Control Groups'!$A:$D,3,FALSE)="Tier 0 – Universal","Yes",IF(COUNTIFS('Tier Category Mapping'!$A:$A,VLOOKUP($A12,'Control Groups'!$A:$D,3,FALSE),'Tier Category Mapping'!$B:$B,C2,'Tier Category Mapping'!$D:$D,"Yes")>0,"Yes","")) | D12: =IF(VLOOKUP($A12,'Control Groups'!$A:$D,3,FALSE)="Tier 0 – Universal","Yes",IF(COUNTIFS('Tier Category Mapping'!$A:$A,VLOOKUP($A12,'Control Groups'!$A:$D,3,FALSE),'Tier Category Mapping'!$B:$B,D2,'Tier Category Mapping'!$D:$D,"Yes")>0,"Yes","")) | E12: =IF(VLOOKUP($A12,'Control Groups'!$A:$D,3,FALSE)="Tier 0 – Universal","Yes",IF(COUNTIFS('Tier Category Mapping'!$A:$A,VLOOKUP($A12,'Control Groups'!$A:$D,3,FALSE),'Tier Category Mapping'!$B:$B,E2,'Tier Category Mapping'!$D:$D,"Yes")>0,"Yes","")) | F12: =IF(VLOOKUP($A12,'Control Groups'!$A:$D,3,FALSE)="Tier 0 – Universal","Yes",IF(COUNTIFS('Tier Category Mapping'!$A:$A,VLOOKUP($A12,'Control Groups'!$A:$D,3,FALSE),'Tier Category Mapping'!$B:$B,F2,'Tier Category Mapping'!$D:$D,"Yes")>0,"Yes","")) | G12: =IF(VLOOKUP($A12,'Control Groups'!$A:$D,3,FALSE)="Tier 0 – Universal","Yes",IF(COUNTIFS('Tier Category Mapping'!$A:$A,VLOOKUP($A12,'Control Groups'!$A:$D,3,FALSE),'Tier Category Mapping'!$B:$B,G2,'Tier Category Mapping'!$D:$D,"Yes")>0,"Yes","")) | H12: =IF(VLOOKUP($A12,'Control Groups'!$A:$D,3,FALSE)="Tier 0 – Universal","Yes",IF(COUNTIFS('Tier Category Mapping'!$A:$A,VLOOKUP($A12,'Control Groups'!$A:$D,3,FALSE),'Tier Category Mapping'!$B:$B,H2,'Tier Category Mapping'!$D:$D,"Yes")>0,"Yes","")) | I12: =IF(VLOOKUP($A12,'Control Groups'!$A:$D,3,FALSE)="Tier 0 – Universal","Yes",IF(COUNTIFS('Tier Category Mapping'!$A:$A,VLOOKUP($A12,'Control Groups'!$A:$D,3,FALSE),'Tier Category Mapping'!$B:$B,I2,'Tier Category Mapping'!$D:$D,"Yes")>0,"Yes","")) | J12: =IF(VLOOKUP($A12,'Control Groups'!$A:$D,3,FALSE)="Tier 0 – Universal","Yes",IF(COUNTIFS('Tier Category Mapping'!$A:$A,VLOOKUP($A12,'Control Groups'!$A:$D,3,FALSE),'Tier Category Mapping'!$B:$B,J2,'Tier Category Mapping'!$D:$D,"Yes")>0,"Yes","")) | ... W12: =IF(VLOOKUP($A12,'Control Groups'!$A:$D,3,FALSE)="Tier 0 – Universal","Yes",IF(COUNTIFS('Tier Category Mapping'!$A:$A,VLOOKUP($A12,'Control Groups'!$A:$D,3,FALSE),'Tier Category Mapping'!$B:$B,W2,'Tier Category Mapping'!$D:$D,"Yes")>0,"Yes",""))
A13: LM-01 | B13: System logging enabled | C13: =IF(VLOOKUP($A13,'Control Groups'!$A:$D,3,FALSE)="Tier 0 – Universal","Yes",IF(COUNTIFS('Tier Category Mapping'!$A:$A,VLOOKUP($A13,'Control Groups'!$A:$D,3,FALSE),'Tier Category Mapping'!$B:$B,C2,'Tier Category Mapping'!$D:$D,"Yes")>0,"Yes","")) | D13: =IF(VLOOKUP($A13,'Control Groups'!$A:$D,3,FALSE)="Tier 0 – Universal","Yes",IF(COUNTIFS('Tier Category Mapping'!$A:$A,VLOOKUP($A13,'Control Groups'!$A:$D,3,FALSE),'Tier Category Mapping'!$B:$B,D2,'Tier Category Mapping'!$D:$D,"Yes")>0,"Yes","")) | E13: =IF(VLOOKUP($A13,'Control Groups'!$A:$D,3,FALSE)="Tier 0 – Universal","Yes",IF(COUNTIFS('Tier Category Mapping'!$A:$A,VLOOKUP($A13,'Control Groups'!$A:$D,3,FALSE),'Tier Category Mapping'!$B:$B,E2,'Tier Category Mapping'!$D:$D,"Yes")>0,"Yes","")) | F13: =IF(VLOOKUP($A13,'Control Groups'!$A:$D,3,FALSE)="Tier 0 – Universal","Yes",IF(COUNTIFS('Tier Category Mapping'!$A:$A,VLOOKUP($A13,'Control Groups'!$A:$D,3,FALSE),'Tier Category Mapping'!$B:$B,F2,'Tier Category Mapping'!$D:$D,"Yes")>0,"Yes","")) | G13: =IF(VLOOKUP($A13,'Control Groups'!$A:$D,3,FALSE)="Tier 0 – Universal","Yes",IF(COUNTIFS('Tier Category Mapping'!$A:$A,VLOOKUP($A13,'Control Groups'!$A:$D,3,FALSE),'Tier Category Mapping'!$B:$B,G2,'Tier Category Mapping'!$D:$D,"Yes")>0,"Yes","")) | H13: =IF(VLOOKUP($A13,'Control Groups'!$A:$D,3,FALSE)="Tier 0 – Universal","Yes",IF(COUNTIFS('Tier Category Mapping'!$A:$A,VLOOKUP($A13,'Control Groups'!$A:$D,3,FALSE),'Tier Category Mapping'!$B:$B,H2,'Tier Category Mapping'!$D:$D,"Yes")>0,"Yes","")) | I13: =IF(VLOOKUP($A13,'Control Groups'!$A:$D,3,FALSE)="Tier 0 – Universal","Yes",IF(COUNTIFS('Tier Category Mapping'!$A:$A,VLOOKUP($A13,'Control Groups'!$A:$D,3,FALSE),'Tier Category Mapping'!$B:$B,I2,'Tier Category Mapping'!$D:$D,"Yes")>0,"Yes","")) | J13: =IF(VLOOKUP($A13,'Control Groups'!$A:$D,3,FALSE)="Tier 0 – Universal","Yes",IF(COUNTIFS('Tier Category Mapping'!$A:$A,VLOOKUP($A13,'Control Groups'!$A:$D,3,FALSE),'Tier Category Mapping'!$B:$B,J2,'Tier Category Mapping'!$D:$D,"Yes")>0,"Yes","")) | ... W13: =IF(VLOOKUP($A13,'Control Groups'!$A:$D,3,FALSE)="Tier 0 – Universal","Yes",IF(COUNTIFS('Tier Category Mapping'!$A:$A,VLOOKUP($A13,'Control Groups'!$A:$D,3,FALSE),'Tier Category Mapping'!$B:$B,W2,'Tier Category Mapping'!$D:$D,"Yes")>0,"Yes",""))
A14: LM-02 | B14: Logs forwarded centrally | C14: =IF(VLOOKUP($A14,'Control Groups'!$A:$D,3,FALSE)="Tier 0 – Universal","Yes",IF(COUNTIFS('Tier Category Mapping'!$A:$A,VLOOKUP($A14,'Control Groups'!$A:$D,3,FALSE),'Tier Category Mapping'!$B:$B,C2,'Tier Category Mapping'!$D:$D,"Yes")>0,"Yes","")) | D14: =IF(VLOOKUP($A14,'Control Groups'!$A:$D,3,FALSE)="Tier 0 – Universal","Yes",IF(COUNTIFS('Tier Category Mapping'!$A:$A,VLOOKUP($A14,'Control Groups'!$A:$D,3,FALSE),'Tier Category Mapping'!$B:$B,D2,'Tier Category Mapping'!$D:$D,"Yes")>0,"Yes","")) | E14: =IF(VLOOKUP($A14,'Control Groups'!$A:$D,3,FALSE)="Tier 0 – Universal","Yes",IF(COUNTIFS('Tier Category Mapping'!$A:$A,VLOOKUP($A14,'Control Groups'!$A:$D,3,FALSE),'Tier Category Mapping'!$B:$B,E2,'Tier Category Mapping'!$D:$D,"Yes")>0,"Yes","")) | F14: =IF(VLOOKUP($A14,'Control Groups'!$A:$D,3,FALSE)="Tier 0 – Universal","Yes",IF(COUNTIFS('Tier Category Mapping'!$A:$A,VLOOKUP($A14,'Control Groups'!$A:$D,3,FALSE),'Tier Category Mapping'!$B:$B,F2,'Tier Category Mapping'!$D:$D,"Yes")>0,"Yes","")) | G14: =IF(VLOOKUP($A14,'Control Groups'!$A:$D,3,FALSE)="Tier 0 – Universal","Yes",IF(COUNTIFS('Tier Category Mapping'!$A:$A,VLOOKUP($A14,'Control Groups'!$A:$D,3,FALSE),'Tier Category Mapping'!$B:$B,G2,'Tier Category Mapping'!$D:$D,"Yes")>0,"Yes","")) | H14: =IF(VLOOKUP($A14,'Control Groups'!$A:$D,3,FALSE)="Tier 0 – Universal","Yes",IF(COUNTIFS('Tier Category Mapping'!$A:$A,VLOOKUP($A14,'Control Groups'!$A:$D,3,FALSE),'Tier Category Mapping'!$B:$B,H2,'Tier Category Mapping'!$D:$D,"Yes")>0,"Yes","")) | I14: =IF(VLOOKUP($A14,'Control Groups'!$A:$D,3,FALSE)="Tier 0 – Universal","Yes",IF(COUNTIFS('Tier Category Mapping'!$A:$A,VLOOKUP($A14,'Control Groups'!$A:$D,3,FALSE),'Tier Category Mapping'!$B:$B,I2,'Tier Category Mapping'!$D:$D,"Yes")>0,"Yes","")) | J14: =IF(VLOOKUP($A14,'Control Groups'!$A:$D,3,FALSE)="Tier 0 – Universal","Yes",IF(COUNTIFS('Tier Category Mapping'!$A:$A,VLOOKUP($A14,'Control Groups'!$A:$D,3,FALSE),'Tier Category Mapping'!$B:$B,J2,'Tier Category Mapping'!$D:$D,"Yes")>0,"Yes","")) | ... W14: =IF(VLOOKUP($A14,'Control Groups'!$A:$D,3,FALSE)="Tier 0 – Universal","Yes",IF(COUNTIFS('Tier Category Mapping'!$A:$A,VLOOKUP($A14,'Control Groups'!$A:$D,3,FALSE),'Tier Category Mapping'!$B:$B,W2,'Tier Category Mapping'!$D:$D,"Yes")>0,"Yes",""))
A15: LM-03 | B15: Time synchronization enabled | C15: =IF(VLOOKUP($A15,'Control Groups'!$A:$D,3,FALSE)="Tier 0 – Universal","Yes",IF(COUNTIFS('Tier Category Mapping'!$A:$A,VLOOKUP($A15,'Control Groups'!$A:$D,3,FALSE),'Tier Category Mapping'!$B:$B,C2,'Tier Category Mapping'!$D:$D,"Yes")>0,"Yes","")) | D15: =IF(VLOOKUP($A15,'Control Groups'!$A:$D,3,FALSE)="Tier 0 – Universal","Yes",IF(COUNTIFS('Tier Category Mapping'!$A:$A,VLOOKUP($A15,'Control Groups'!$A:$D,3,FALSE),'Tier Category Mapping'!$B:$B,D2,'Tier Category Mapping'!$D:$D,"Yes")>0,"Yes","")) | E15: =IF(VLOOKUP($A15,'Control Groups'!$A:$D,3,FALSE)="Tier 0 – Universal","Yes",IF(COUNTIFS('Tier Category Mapping'!$A:$A,VLOOKUP($A15,'Control Groups'!$A:$D,3,FALSE),'Tier Category Mapping'!$B:$B,E2,'Tier Category Mapping'!$D:$D,"Yes")>0,"Yes","")) | F15: =IF(VLOOKUP($A15,'Control Groups'!$A:$D,3,FALSE)="Tier 0 – Universal","Yes",IF(COUNTIFS('Tier Category Mapping'!$A:$A,VLOOKUP($A15,'Control Groups'!$A:$D,3,FALSE),'Tier Category Mapping'!$B:$B,F2,'Tier Category Mapping'!$D:$D,"Yes")>0,"Yes","")) | G15: =IF(VLOOKUP($A15,'Control Groups'!$A:$D,3,FALSE)="Tier 0 – Universal","Yes",IF(COUNTIFS('Tier Category Mapping'!$A:$A,VLOOKUP($A15,'Control Groups'!$A:$D,3,FALSE),'Tier Category Mapping'!$B:$B,G2,'Tier Category Mapping'!$D:$D,"Yes")>0,"Yes","")) | H15: =IF(VLOOKUP($A15,'Control Groups'!$A:$D,3,FALSE)="Tier 0 – Universal","Yes",IF(COUNTIFS('Tier Category Mapping'!$A:$A,VLOOKUP($A15,'Control Groups'!$A:$D,3,FALSE),'Tier Category Mapping'!$B:$B,H2,'Tier Category Mapping'!$D:$D,"Yes")>0,"Yes","")) | I15: =IF(VLOOKUP($A15,'Control Groups'!$A:$D,3,FALSE)="Tier 0 – Universal","Yes",IF(COUNTIFS('Tier Category Mapping'!$A:$A,VLOOKUP($A15,'Control Groups'!$A:$D,3,FALSE),'Tier Category Mapping'!$B:$B,I2,'Tier Category Mapping'!$D:$D,"Yes")>0,"Yes","")) | J15: =IF(VLOOKUP($A15,'Control Groups'!$A:$D,3,FALSE)="Tier 0 – Universal","Yes",IF(COUNTIFS('Tier Category Mapping'!$A:$A,VLOOKUP($A15,'Control Groups'!$A:$D,3,FALSE),'Tier Category Mapping'!$B:$B,J2,'Tier Category Mapping'!$D:$D,"Yes")>0,"Yes","")) | ... W15: =IF(VLOOKUP($A15,'Control Groups'!$A:$D,3,FALSE)="Tier 0 – Universal","Yes",IF(COUNTIFS('Tier Category Mapping'!$A:$A,VLOOKUP($A15,'Control Groups'!$A:$D,3,FALSE),'Tier Category Mapping'!$B:$B,W2,'Tier Category Mapping'!$D:$D,"Yes")>0,"Yes",""))
A16: PM-01 | B16: OS patching enabled | C16: =IF(VLOOKUP($A16,'Control Groups'!$A:$D,3,FALSE)="Tier 0 – Universal","Yes",IF(COUNTIFS('Tier Category Mapping'!$A:$A,VLOOKUP($A16,'Control Groups'!$A:$D,3,FALSE),'Tier Category Mapping'!$B:$B,C2,'Tier Category Mapping'!$D:$D,"Yes")>0,"Yes","")) | D16: =IF(VLOOKUP($A16,'Control Groups'!$A:$D,3,FALSE)="Tier 0 – Universal","Yes",IF(COUNTIFS('Tier Category Mapping'!$A:$A,VLOOKUP($A16,'Control Groups'!$A:$D,3,FALSE),'Tier Category Mapping'!$B:$B,D2,'Tier Category Mapping'!$D:$D,"Yes")>0,"Yes","")) | E16: =IF(VLOOKUP($A16,'Control Groups'!$A:$D,3,FALSE)="Tier 0 – Universal","Yes",IF(COUNTIFS('Tier Category Mapping'!$A:$A,VLOOKUP($A16,'Control Groups'!$A:$D,3,FALSE),'Tier Category Mapping'!$B:$B,E2,'Tier Category Mapping'!$D:$D,"Yes")>0,"Yes","")) | F16: =IF(VLOOKUP($A16,'Control Groups'!$A:$D,3,FALSE)="Tier 0 – Universal","Yes",IF(COUNTIFS('Tier Category Mapping'!$A:$A,VLOOKUP($A16,'Control Groups'!$A:$D,3,FALSE),'Tier Category Mapping'!$B:$B,F2,'Tier Category Mapping'!$D:$D,"Yes")>0,"Yes","")) | G16: =IF(VLOOKUP($A16,'Control Groups'!$A:$D,3,FALSE)="Tier 0 – Universal","Yes",IF(COUNTIFS('Tier Category Mapping'!$A:$A,VLOOKUP($A16,'Control Groups'!$A:$D,3,FALSE),'Tier Category Mapping'!$B:$B,G2,'Tier Category Mapping'!$D:$D,"Yes")>0,"Yes","")) | H16: =IF(VLOOKUP($A16,'Control Groups'!$A:$D,3,FALSE)="Tier 0 – Universal","Yes",IF(COUNTIFS('Tier Category Mapping'!$A:$A,VLOOKUP($A16,'Control Groups'!$A:$D,3,FALSE),'Tier Category Mapping'!$B:$B,H2,'Tier Category Mapping'!$D:$D,"Yes")>0,"Yes","")) | I16: =IF(VLOOKUP($A16,'Control Groups'!$A:$D,3,FALSE)="Tier 0 – Universal","Yes",IF(COUNTIFS('Tier Category Mapping'!$A:$A,VLOOKUP($A16,'Control Groups'!$A:$D,3,FALSE),'Tier Category Mapping'!$B:$B,I2,'Tier Category Mapping'!$D:$D,"Yes")>0,"Yes","")) | J16: =IF(VLOOKUP($A16,'Control Groups'!$A:$D,3,FALSE)="Tier 0 – Universal","Yes",IF(COUNTIFS('Tier Category Mapping'!$A:$A,VLOOKUP($A16,'Control Groups'!$A:$D,3,FALSE),'Tier Category Mapping'!$B:$B,J2,'Tier Category Mapping'!$D:$D,"Yes")>0,"Yes","")) | ... W16: =IF(VLOOKUP($A16,'Control Groups'!$A:$D,3,FALSE)="Tier 0 – Universal","Yes",IF(COUNTIFS('Tier Category Mapping'!$A:$A,VLOOKUP($A16,'Control Groups'!$A:$D,3,FALSE),'Tier Category Mapping'!$B:$B,W2,'Tier Category Mapping'!$D:$D,"Yes")>0,"Yes",""))
A17: PM-02 | B17: Security patches prioritized | C17: =IF(VLOOKUP($A17,'Control Groups'!$A:$D,3,FALSE)="Tier 0 – Universal","Yes",IF(COUNTIFS('Tier Category Mapping'!$A:$A,VLOOKUP($A17,'Control Groups'!$A:$D,3,FALSE),'Tier Category Mapping'!$B:$B,C2,'Tier Category Mapping'!$D:$D,"Yes")>0,"Yes","")) | D17: =IF(VLOOKUP($A17,'Control Groups'!$A:$D,3,FALSE)="Tier 0 – Universal","Yes",IF(COUNTIFS('Tier Category Mapping'!$A:$A,VLOOKUP($A17,'Control Groups'!$A:$D,3,FALSE),'Tier Category Mapping'!$B:$B,D2,'Tier Category Mapping'!$D:$D,"Yes")>0,"Yes","")) | E17: =IF(VLOOKUP($A17,'Control Groups'!$A:$D,3,FALSE)="Tier 0 – Universal","Yes",IF(COUNTIFS('Tier Category Mapping'!$A:$A,VLOOKUP($A17,'Control Groups'!$A:$D,3,FALSE),'Tier Category Mapping'!$B:$B,E2,'Tier Category Mapping'!$D:$D,"Yes")>0,"Yes","")) | F17: =IF(VLOOKUP($A17,'Control Groups'!$A:$D,3,FALSE)="Tier 0 – Universal","Yes",IF(COUNTIFS('Tier Category Mapping'!$A:$A,VLOOKUP($A17,'Control Groups'!$A:$D,3,FALSE),'Tier Category Mapping'!$B:$B,F2,'Tier Category Mapping'!$D:$D,"Yes")>0,"Yes","")) | G17: =IF(VLOOKUP($A17,'Control Groups'!$A:$D,3,FALSE)="Tier 0 – Universal","Yes",IF(COUNTIFS('Tier Category Mapping'!$A:$A,VLOOKUP($A17,'Control Groups'!$A:$D,3,FALSE),'Tier Category Mapping'!$B:$B,G2,'Tier Category Mapping'!$D:$D,"Yes")>0,"Yes","")) | H17: =IF(VLOOKUP($A17,'Control Groups'!$A:$D,3,FALSE)="Tier 0 – Universal","Yes",IF(COUNTIFS('Tier Category Mapping'!$A:$A,VLOOKUP($A17,'Control Groups'!$A:$D,3,FALSE),'Tier Category Mapping'!$B:$B,H2,'Tier Category Mapping'!$D:$D,"Yes")>0,"Yes","")) | I17: =IF(VLOOKUP($A17,'Control Groups'!$A:$D,3,FALSE)="Tier 0 – Universal","Yes",IF(COUNTIFS('Tier Category Mapping'!$A:$A,VLOOKUP($A17,'Control Groups'!$A:$D,3,FALSE),'Tier Category Mapping'!$B:$B,I2,'Tier Category Mapping'!$D:$D,"Yes")>0,"Yes","")) | J17: =IF(VLOOKUP($A17,'Control Groups'!$A:$D,3,FALSE)="Tier 0 – Universal","Yes",IF(COUNTIFS('Tier Category Mapping'!$A:$A,VLOOKUP($A17,'Control Groups'!$A:$D,3,FALSE),'Tier Category Mapping'!$B:$B,J2,'Tier Category Mapping'!$D:$D,"Yes")>0,"Yes","")) | ... W17: =IF(VLOOKUP($A17,'Control Groups'!$A:$D,3,FALSE)="Tier 0 – Universal","Yes",IF(COUNTIFS('Tier Category Mapping'!$A:$A,VLOOKUP($A17,'Control Groups'!$A:$D,3,FALSE),'Tier Category Mapping'!$B:$B,W2,'Tier Category Mapping'!$D:$D,"Yes")>0,"Yes",""))
A18: BK-01 | B18: Backups enabled | C18: =IF(VLOOKUP($A18,'Control Groups'!$A:$D,3,FALSE)="Tier 0 – Universal","Yes",IF(COUNTIFS('Tier Category Mapping'!$A:$A,VLOOKUP($A18,'Control Groups'!$A:$D,3,FALSE),'Tier Category Mapping'!$B:$B,C2,'Tier Category Mapping'!$D:$D,"Yes")>0,"Yes","")) | D18: =IF(VLOOKUP($A18,'Control Groups'!$A:$D,3,FALSE)="Tier 0 – Universal","Yes",IF(COUNTIFS('Tier Category Mapping'!$A:$A,VLOOKUP($A18,'Control Groups'!$A:$D,3,FALSE),'Tier Category Mapping'!$B:$B,D2,'Tier Category Mapping'!$D:$D,"Yes")>0,"Yes","")) | E18: =IF(VLOOKUP($A18,'Control Groups'!$A:$D,3,FALSE)="Tier 0 – Universal","Yes",IF(COUNTIFS('Tier Category Mapping'!$A:$A,VLOOKUP($A18,'Control Groups'!$A:$D,3,FALSE),'Tier Category Mapping'!$B:$B,E2,'Tier Category Mapping'!$D:$D,"Yes")>0,"Yes","")) | F18: =IF(VLOOKUP($A18,'Control Groups'!$A:$D,3,FALSE)="Tier 0 – Universal","Yes",IF(COUNTIFS('Tier Category Mapping'!$A:$A,VLOOKUP($A18,'Control Groups'!$A:$D,3,FALSE),'Tier Category Mapping'!$B:$B,F2,'Tier Category Mapping'!$D:$D,"Yes")>0,"Yes","")) | G18: =IF(VLOOKUP($A18,'Control Groups'!$A:$D,3,FALSE)="Tier 0 – Universal","Yes",IF(COUNTIFS('Tier Category Mapping'!$A:$A,VLOOKUP($A18,'Control Groups'!$A:$D,3,FALSE),'Tier Category Mapping'!$B:$B,G2,'Tier Category Mapping'!$D:$D,"Yes")>0,"Yes","")) | H18: =IF(VLOOKUP($A18,'Control Groups'!$A:$D,3,FALSE)="Tier 0 – Universal","Yes",IF(COUNTIFS('Tier Category Mapping'!$A:$A,VLOOKUP($A18,'Control Groups'!$A:$D,3,FALSE),'Tier Category Mapping'!$B:$B,H2,'Tier Category Mapping'!$D:$D,"Yes")>0,"Yes","")) | I18: =IF(VLOOKUP($A18,'Control Groups'!$A:$D,3,FALSE)="Tier 0 – Universal","Yes",IF(COUNTIFS('Tier Category Mapping'!$A:$A,VLOOKUP($A18,'Control Groups'!$A:$D,3,FALSE),'Tier Category Mapping'!$B:$B,I2,'Tier Category Mapping'!$D:$D,"Yes")>0,"Yes","")) | J18: =IF(VLOOKUP($A18,'Control Groups'!$A:$D,3,FALSE)="Tier 0 – Universal","Yes",IF(COUNTIFS('Tier Category Mapping'!$A:$A,VLOOKUP($A18,'Control Groups'!$A:$D,3,FALSE),'Tier Category Mapping'!$B:$B,J2,'Tier Category Mapping'!$D:$D,"Yes")>0,"Yes","")) | ... W18: =IF(VLOOKUP($A18,'Control Groups'!$A:$D,3,FALSE)="Tier 0 – Universal","Yes",IF(COUNTIFS('Tier Category Mapping'!$A:$A,VLOOKUP($A18,'Control Groups'!$A:$D,3,FALSE),'Tier Category Mapping'!$B:$B,W2,'Tier Category Mapping'!$D:$D,"Yes")>0,"Yes",""))
A19: BK-02 | B19: Backups tested periodically | C19: =IF(VLOOKUP($A19,'Control Groups'!$A:$D,3,FALSE)="Tier 0 – Universal","Yes",IF(COUNTIFS('Tier Category Mapping'!$A:$A,VLOOKUP($A19,'Control Groups'!$A:$D,3,FALSE),'Tier Category Mapping'!$B:$B,C2,'Tier Category Mapping'!$D:$D,"Yes")>0,"Yes","")) | D19: =IF(VLOOKUP($A19,'Control Groups'!$A:$D,3,FALSE)="Tier 0 – Universal","Yes",IF(COUNTIFS('Tier Category Mapping'!$A:$A,VLOOKUP($A19,'Control Groups'!$A:$D,3,FALSE),'Tier Category Mapping'!$B:$B,D2,'Tier Category Mapping'!$D:$D,"Yes")>0,"Yes","")) | E19: =IF(VLOOKUP($A19,'Control Groups'!$A:$D,3,FALSE)="Tier 0 – Universal","Yes",IF(COUNTIFS('Tier Category Mapping'!$A:$A,VLOOKUP($A19,'Control Groups'!$A:$D,3,FALSE),'Tier Category Mapping'!$B:$B,E2,'Tier Category Mapping'!$D:$D,"Yes")>0,"Yes","")) | F19: =IF(VLOOKUP($A19,'Control Groups'!$A:$D,3,FALSE)="Tier 0 – Universal","Yes",IF(COUNTIFS('Tier Category Mapping'!$A:$A,VLOOKUP($A19,'Control Groups'!$A:$D,3,FALSE),'Tier Category Mapping'!$B:$B,F2,'Tier Category Mapping'!$D:$D,"Yes")>0,"Yes","")) | G19: =IF(VLOOKUP($A19,'Control Groups'!$A:$D,3,FALSE)="Tier 0 – Universal","Yes",IF(COUNTIFS('Tier Category Mapping'!$A:$A,VLOOKUP($A19,'Control Groups'!$A:$D,3,FALSE),'Tier Category Mapping'!$B:$B,G2,'Tier Category Mapping'!$D:$D,"Yes")>0,"Yes","")) | H19: =IF(VLOOKUP($A19,'Control Groups'!$A:$D,3,FALSE)="Tier 0 – Universal","Yes",IF(COUNTIFS('Tier Category Mapping'!$A:$A,VLOOKUP($A19,'Control Groups'!$A:$D,3,FALSE),'Tier Category Mapping'!$B:$B,H2,'Tier Category Mapping'!$D:$D,"Yes")>0,"Yes","")) | I19: =IF(VLOOKUP($A19,'Control Groups'!$A:$D,3,FALSE)="Tier 0 – Universal","Yes",IF(COUNTIFS('Tier Category Mapping'!$A:$A,VLOOKUP($A19,'Control Groups'!$A:$D,3,FALSE),'Tier Category Mapping'!$B:$B,I2,'Tier Category Mapping'!$D:$D,"Yes")>0,"Yes","")) | J19: =IF(VLOOKUP($A19,'Control Groups'!$A:$D,3,FALSE)="Tier 0 – Universal","Yes",IF(COUNTIFS('Tier Category Mapping'!$A:$A,VLOOKUP($A19,'Control Groups'!$A:$D,3,FALSE),'Tier Category Mapping'!$B:$B,J2,'Tier Category Mapping'!$D:$D,"Yes")>0,"Yes","")) | ... W19: =IF(VLOOKUP($A19,'Control Groups'!$A:$D,3,FALSE)="Tier 0 – Universal","Yes",IF(COUNTIFS('Tier Category Mapping'!$A:$A,VLOOKUP($A19,'Control Groups'!$A:$D,3,FALSE),'Tier Category Mapping'!$B:$B,W2,'Tier Category Mapping'!$D:$D,"Yes")>0,"Yes",""))
A20: SOP-01 | B20: Registered in Source of Truth | C20: =IF(VLOOKUP($A20,'Control Groups'!$A:$D,3,FALSE)="Tier 0 – Universal","Yes",IF(COUNTIFS('Tier Category Mapping'!$A:$A,VLOOKUP($A20,'Control Groups'!$A:$D,3,FALSE),'Tier Category Mapping'!$B:$B,C2,'Tier Category Mapping'!$D:$D,"Yes")>0,"Yes","")) | D20: =IF(VLOOKUP($A20,'Control Groups'!$A:$D,3,FALSE)="Tier 0 – Universal","Yes",IF(COUNTIFS('Tier Category Mapping'!$A:$A,VLOOKUP($A20,'Control Groups'!$A:$D,3,FALSE),'Tier Category Mapping'!$B:$B,D2,'Tier Category Mapping'!$D:$D,"Yes")>0,"Yes","")) | E20: =IF(VLOOKUP($A20,'Control Groups'!$A:$D,3,FALSE)="Tier 0 – Universal","Yes",IF(COUNTIFS('Tier Category Mapping'!$A:$A,VLOOKUP($A20,'Control Groups'!$A:$D,3,FALSE),'Tier Category Mapping'!$B:$B,E2,'Tier Category Mapping'!$D:$D,"Yes")>0,"Yes","")) | F20: =IF(VLOOKUP($A20,'Control Groups'!$A:$D,3,FALSE)="Tier 0 – Universal","Yes",IF(COUNTIFS('Tier Category Mapping'!$A:$A,VLOOKUP($A20,'Control Groups'!$A:$D,3,FALSE),'Tier Category Mapping'!$B:$B,F2,'Tier Category Mapping'!$D:$D,"Yes")>0,"Yes","")) | G20: =IF(VLOOKUP($A20,'Control Groups'!$A:$D,3,FALSE)="Tier 0 – Universal","Yes",IF(COUNTIFS('Tier Category Mapping'!$A:$A,VLOOKUP($A20,'Control Groups'!$A:$D,3,FALSE),'Tier Category Mapping'!$B:$B,G2,'Tier Category Mapping'!$D:$D,"Yes")>0,"Yes","")) | H20: =IF(VLOOKUP($A20,'Control Groups'!$A:$D,3,FALSE)="Tier 0 – Universal","Yes",IF(COUNTIFS('Tier Category Mapping'!$A:$A,VLOOKUP($A20,'Control Groups'!$A:$D,3,FALSE),'Tier Category Mapping'!$B:$B,H2,'Tier Category Mapping'!$D:$D,"Yes")>0,"Yes","")) | I20: =IF(VLOOKUP($A20,'Control Groups'!$A:$D,3,FALSE)="Tier 0 – Universal","Yes",IF(COUNTIFS('Tier Category Mapping'!$A:$A,VLOOKUP($A20,'Control Groups'!$A:$D,3,FALSE),'Tier Category Mapping'!$B:$B,I2,'Tier Category Mapping'!$D:$D,"Yes")>0,"Yes","")) | J20: =IF(VLOOKUP($A20,'Control Groups'!$A:$D,3,FALSE)="Tier 0 – Universal","Yes",IF(COUNTIFS('Tier Category Mapping'!$A:$A,VLOOKUP($A20,'Control Groups'!$A:$D,3,FALSE),'Tier Category Mapping'!$B:$B,J2,'Tier Category Mapping'!$D:$D,"Yes")>0,"Yes","")) | ... W20: =IF(VLOOKUP($A20,'Control Groups'!$A:$D,3,FALSE)="Tier 0 – Universal","Yes",IF(COUNTIFS('Tier Category Mapping'!$A:$A,VLOOKUP($A20,'Control Groups'!$A:$D,3,FALSE),'Tier Category Mapping'!$B:$B,W2,'Tier Category Mapping'!$D:$D,"Yes")>0,"Yes",""))
A21: SOP-02 | B21: Owner and environment assigned | C21: =IF(VLOOKUP($A21,'Control Groups'!$A:$D,3,FALSE)="Tier 0 – Universal","Yes",IF(COUNTIFS('Tier Category Mapping'!$A:$A,VLOOKUP($A21,'Control Groups'!$A:$D,3,FALSE),'Tier Category Mapping'!$B:$B,C2,'Tier Category Mapping'!$D:$D,"Yes")>0,"Yes","")) | D21: =IF(VLOOKUP($A21,'Control Groups'!$A:$D,3,FALSE)="Tier 0 – Universal","Yes",IF(COUNTIFS('Tier Category Mapping'!$A:$A,VLOOKUP($A21,'Control Groups'!$A:$D,3,FALSE),'Tier Category Mapping'!$B:$B,D2,'Tier Category Mapping'!$D:$D,"Yes")>0,"Yes","")) | E21: =IF(VLOOKUP($A21,'Control Groups'!$A:$D,3,FALSE)="Tier 0 – Universal","Yes",IF(COUNTIFS('Tier Category Mapping'!$A:$A,VLOOKUP($A21,'Control Groups'!$A:$D,3,FALSE),'Tier Category Mapping'!$B:$B,E2,'Tier Category Mapping'!$D:$D,"Yes")>0,"Yes","")) | F21: =IF(VLOOKUP($A21,'Control Groups'!$A:$D,3,FALSE)="Tier 0 – Universal","Yes",IF(COUNTIFS('Tier Category Mapping'!$A:$A,VLOOKUP($A21,'Control Groups'!$A:$D,3,FALSE),'Tier Category Mapping'!$B:$B,F2,'Tier Category Mapping'!$D:$D,"Yes")>0,"Yes","")) | G21: =IF(VLOOKUP($A21,'Control Groups'!$A:$D,3,FALSE)="Tier 0 – Universal","Yes",IF(COUNTIFS('Tier Category Mapping'!$A:$A,VLOOKUP($A21,'Control Groups'!$A:$D,3,FALSE),'Tier Category Mapping'!$B:$B,G2,'Tier Category Mapping'!$D:$D,"Yes")>0,"Yes","")) | H21: =IF(VLOOKUP($A21,'Control Groups'!$A:$D,3,FALSE)="Tier 0 – Universal","Yes",IF(COUNTIFS('Tier Category Mapping'!$A:$A,VLOOKUP($A21,'Control Groups'!$A:$D,3,FALSE),'Tier Category Mapping'!$B:$B,H2,'Tier Category Mapping'!$D:$D,"Yes")>0,"Yes","")) | I21: =IF(VLOOKUP($A21,'Control Groups'!$A:$D,3,FALSE)="Tier 0 – Universal","Yes",IF(COUNTIFS('Tier Category Mapping'!$A:$A,VLOOKUP($A21,'Control Groups'!$A:$D,3,FALSE),'Tier Category Mapping'!$B:$B,I2,'Tier Category Mapping'!$D:$D,"Yes")>0,"Yes","")) | J21: =IF(VLOOKUP($A21,'Control Groups'!$A:$D,3,FALSE)="Tier 0 – Universal","Yes",IF(COUNTIFS('Tier Category Mapping'!$A:$A,VLOOKUP($A21,'Control Groups'!$A:$D,3,FALSE),'Tier Category Mapping'!$B:$B,J2,'Tier Category Mapping'!$D:$D,"Yes")>0,"Yes","")) | ... W21: =IF(VLOOKUP($A21,'Control Groups'!$A:$D,3,FALSE)="Tier 0 – Universal","Yes",IF(COUNTIFS('Tier Category Mapping'!$A:$A,VLOOKUP($A21,'Control Groups'!$A:$D,3,FALSE),'Tier Category Mapping'!$B:$B,W2,'Tier Category Mapping'!$D:$D,"Yes")>0,"Yes",""))
A22: SOP-03 | B22: Secure baseline applied during build | C22: =IF(VLOOKUP($A22,'Control Groups'!$A:$D,3,FALSE)="Tier 0 – Universal","Yes",IF(COUNTIFS('Tier Category Mapping'!$A:$A,VLOOKUP($A22,'Control Groups'!$A:$D,3,FALSE),'Tier Category Mapping'!$B:$B,C2,'Tier Category Mapping'!$D:$D,"Yes")>0,"Yes","")) | D22: =IF(VLOOKUP($A22,'Control Groups'!$A:$D,3,FALSE)="Tier 0 – Universal","Yes",IF(COUNTIFS('Tier Category Mapping'!$A:$A,VLOOKUP($A22,'Control Groups'!$A:$D,3,FALSE),'Tier Category Mapping'!$B:$B,D2,'Tier Category Mapping'!$D:$D,"Yes")>0,"Yes","")) | E22: =IF(VLOOKUP($A22,'Control Groups'!$A:$D,3,FALSE)="Tier 0 – Universal","Yes",IF(COUNTIFS('Tier Category Mapping'!$A:$A,VLOOKUP($A22,'Control Groups'!$A:$D,3,FALSE),'Tier Category Mapping'!$B:$B,E2,'Tier Category Mapping'!$D:$D,"Yes")>0,"Yes","")) | F22: =IF(VLOOKUP($A22,'Control Groups'!$A:$D,3,FALSE)="Tier 0 – Universal","Yes",IF(COUNTIFS('Tier Category Mapping'!$A:$A,VLOOKUP($A22,'Control Groups'!$A:$D,3,FALSE),'Tier Category Mapping'!$B:$B,F2,'Tier Category Mapping'!$D:$D,"Yes")>0,"Yes","")) | G22: =IF(VLOOKUP($A22,'Control Groups'!$A:$D,3,FALSE)="Tier 0 – Universal","Yes",IF(COUNTIFS('Tier Category Mapping'!$A:$A,VLOOKUP($A22,'Control Groups'!$A:$D,3,FALSE),'Tier Category Mapping'!$B:$B,G2,'Tier Category Mapping'!$D:$D,"Yes")>0,"Yes","")) | H22: =IF(VLOOKUP($A22,'Control Groups'!$A:$D,3,FALSE)="Tier 0 – Universal","Yes",IF(COUNTIFS('Tier Category Mapping'!$A:$A,VLOOKUP($A22,'Control Groups'!$A:$D,3,FALSE),'Tier Category Mapping'!$B:$B,H2,'Tier Category Mapping'!$D:$D,"Yes")>0,"Yes","")) | I22: =IF(VLOOKUP($A22,'Control Groups'!$A:$D,3,FALSE)="Tier 0 – Universal","Yes",IF(COUNTIFS('Tier Category Mapping'!$A:$A,VLOOKUP($A22,'Control Groups'!$A:$D,3,FALSE),'Tier Category Mapping'!$B:$B,I2,'Tier Category Mapping'!$D:$D,"Yes")>0,"Yes","")) | J22: =IF(VLOOKUP($A22,'Control Groups'!$A:$D,3,FALSE)="Tier 0 – Universal","Yes",IF(COUNTIFS('Tier Category Mapping'!$A:$A,VLOOKUP($A22,'Control Groups'!$A:$D,3,FALSE),'Tier Category Mapping'!$B:$B,J2,'Tier Category Mapping'!$D:$D,"Yes")>0,"Yes","")) | ... W22: =IF(VLOOKUP($A22,'Control Groups'!$A:$D,3,FALSE)="Tier 0 – Universal","Yes",IF(COUNTIFS('Tier Category Mapping'!$A:$A,VLOOKUP($A22,'Control Groups'!$A:$D,3,FALSE),'Tier Category Mapping'!$B:$B,W2,'Tier Category Mapping'!$D:$D,"Yes")>0,"Yes",""))
A23: SOP-04 | B23: Endpoint protection installed | C23: =IF(VLOOKUP($A23,'Control Groups'!$A:$D,3,FALSE)="Tier 0 – Universal","Yes",IF(COUNTIFS('Tier Category Mapping'!$A:$A,VLOOKUP($A23,'Control Groups'!$A:$D,3,FALSE),'Tier Category Mapping'!$B:$B,C2,'Tier Category Mapping'!$D:$D,"Yes")>0,"Yes","")) | D23: =IF(VLOOKUP($A23,'Control Groups'!$A:$D,3,FALSE)="Tier 0 – Universal","Yes",IF(COUNTIFS('Tier Category Mapping'!$A:$A,VLOOKUP($A23,'Control Groups'!$A:$D,3,FALSE),'Tier Category Mapping'!$B:$B,D2,'Tier Category Mapping'!$D:$D,"Yes")>0,"Yes","")) | E23: =IF(VLOOKUP($A23,'Control Groups'!$A:$D,3,FALSE)="Tier 0 – Universal","Yes",IF(COUNTIFS('Tier Category Mapping'!$A:$A,VLOOKUP($A23,'Control Groups'!$A:$D,3,FALSE),'Tier Category Mapping'!$B:$B,E2,'Tier Category Mapping'!$D:$D,"Yes")>0,"Yes","")) | F23: =IF(VLOOKUP($A23,'Control Groups'!$A:$D,3,FALSE)="Tier 0 – Universal","Yes",IF(COUNTIFS('Tier Category Mapping'!$A:$A,VLOOKUP($A23,'Control Groups'!$A:$D,3,FALSE),'Tier Category Mapping'!$B:$B,F2,'Tier Category Mapping'!$D:$D,"Yes")>0,"Yes","")) | G23: =IF(VLOOKUP($A23,'Control Groups'!$A:$D,3,FALSE)="Tier 0 – Universal","Yes",IF(COUNTIFS('Tier Category Mapping'!$A:$A,VLOOKUP($A23,'Control Groups'!$A:$D,3,FALSE),'Tier Category Mapping'!$B:$B,G2,'Tier Category Mapping'!$D:$D,"Yes")>0,"Yes","")) | H23: =IF(VLOOKUP($A23,'Control Groups'!$A:$D,3,FALSE)="Tier 0 – Universal","Yes",IF(COUNTIFS('Tier Category Mapping'!$A:$A,VLOOKUP($A23,'Control Groups'!$A:$D,3,FALSE),'Tier Category Mapping'!$B:$B,H2,'Tier Category Mapping'!$D:$D,"Yes")>0,"Yes","")) | I23: =IF(VLOOKUP($A23,'Control Groups'!$A:$D,3,FALSE)="Tier 0 – Universal","Yes",IF(COUNTIFS('Tier Category Mapping'!$A:$A,VLOOKUP($A23,'Control Groups'!$A:$D,3,FALSE),'Tier Category Mapping'!$B:$B,I2,'Tier Category Mapping'!$D:$D,"Yes")>0,"Yes","")) | J23: =IF(VLOOKUP($A23,'Control Groups'!$A:$D,3,FALSE)="Tier 0 – Universal","Yes",IF(COUNTIFS('Tier Category Mapping'!$A:$A,VLOOKUP($A23,'Control Groups'!$A:$D,3,FALSE),'Tier Category Mapping'!$B:$B,J2,'Tier Category Mapping'!$D:$D,"Yes")>0,"Yes","")) | ... W23: =IF(VLOOKUP($A23,'Control Groups'!$A:$D,3,FALSE)="Tier 0 – Universal","Yes",IF(COUNTIFS('Tier Category Mapping'!$A:$A,VLOOKUP($A23,'Control Groups'!$A:$D,3,FALSE),'Tier Category Mapping'!$B:$B,W2,'Tier Category Mapping'!$D:$D,"Yes")>0,"Yes",""))
A24: SOP-05 | B24: Logging enabled during build | C24: =IF(VLOOKUP($A24,'Control Groups'!$A:$D,3,FALSE)="Tier 0 – Universal","Yes",IF(COUNTIFS('Tier Category Mapping'!$A:$A,VLOOKUP($A24,'Control Groups'!$A:$D,3,FALSE),'Tier Category Mapping'!$B:$B,C2,'Tier Category Mapping'!$D:$D,"Yes")>0,"Yes","")) | D24: =IF(VLOOKUP($A24,'Control Groups'!$A:$D,3,FALSE)="Tier 0 – Universal","Yes",IF(COUNTIFS('Tier Category Mapping'!$A:$A,VLOOKUP($A24,'Control Groups'!$A:$D,3,FALSE),'Tier Category Mapping'!$B:$B,D2,'Tier Category Mapping'!$D:$D,"Yes")>0,"Yes","")) | E24: =IF(VLOOKUP($A24,'Control Groups'!$A:$D,3,FALSE)="Tier 0 – Universal","Yes",IF(COUNTIFS('Tier Category Mapping'!$A:$A,VLOOKUP($A24,'Control Groups'!$A:$D,3,FALSE),'Tier Category Mapping'!$B:$B,E2,'Tier Category Mapping'!$D:$D,"Yes")>0,"Yes","")) | F24: =IF(VLOOKUP($A24,'Control Groups'!$A:$D,3,FALSE)="Tier 0 – Universal","Yes",IF(COUNTIFS('Tier Category Mapping'!$A:$A,VLOOKUP($A24,'Control Groups'!$A:$D,3,FALSE),'Tier Category Mapping'!$B:$B,F2,'Tier Category Mapping'!$D:$D,"Yes")>0,"Yes","")) | G24: =IF(VLOOKUP($A24,'Control Groups'!$A:$D,3,FALSE)="Tier 0 – Universal","Yes",IF(COUNTIFS('Tier Category Mapping'!$A:$A,VLOOKUP($A24,'Control Groups'!$A:$D,3,FALSE),'Tier Category Mapping'!$B:$B,G2,'Tier Category Mapping'!$D:$D,"Yes")>0,"Yes","")) | H24: =IF(VLOOKUP($A24,'Control Groups'!$A:$D,3,FALSE)="Tier 0 – Universal","Yes",IF(COUNTIFS('Tier Category Mapping'!$A:$A,VLOOKUP($A24,'Control Groups'!$A:$D,3,FALSE),'Tier Category Mapping'!$B:$B,H2,'Tier Category Mapping'!$D:$D,"Yes")>0,"Yes","")) | I24: =IF(VLOOKUP($A24,'Control Groups'!$A:$D,3,FALSE)="Tier 0 – Universal","Yes",IF(COUNTIFS('Tier Category Mapping'!$A:$A,VLOOKUP($A24,'Control Groups'!$A:$D,3,FALSE),'Tier Category Mapping'!$B:$B,I2,'Tier Category Mapping'!$D:$D,"Yes")>0,"Yes","")) | J24: =IF(VLOOKUP($A24,'Control Groups'!$A:$D,3,FALSE)="Tier 0 – Universal","Yes",IF(COUNTIFS('Tier Category Mapping'!$A:$A,VLOOKUP($A24,'Control Groups'!$A:$D,3,FALSE),'Tier Category Mapping'!$B:$B,J2,'Tier Category Mapping'!$D:$D,"Yes")>0,"Yes","")) | ... W24: =IF(VLOOKUP($A24,'Control Groups'!$A:$D,3,FALSE)="Tier 0 – Universal","Yes",IF(COUNTIFS('Tier Category Mapping'!$A:$A,VLOOKUP($A24,'Control Groups'!$A:$D,3,FALSE),'Tier Category Mapping'!$B:$B,W2,'Tier Category Mapping'!$D:$D,"Yes")>0,"Yes",""))
A25: SOP-06 | B25: Hardening checklist validated | C25: =IF(VLOOKUP($A25,'Control Groups'!$A:$D,3,FALSE)="Tier 0 – Universal","Yes",IF(COUNTIFS('Tier Category Mapping'!$A:$A,VLOOKUP($A25,'Control Groups'!$A:$D,3,FALSE),'Tier Category Mapping'!$B:$B,C2,'Tier Category Mapping'!$D:$D,"Yes")>0,"Yes","")) | D25: =IF(VLOOKUP($A25,'Control Groups'!$A:$D,3,FALSE)="Tier 0 – Universal","Yes",IF(COUNTIFS('Tier Category Mapping'!$A:$A,VLOOKUP($A25,'Control Groups'!$A:$D,3,FALSE),'Tier Category Mapping'!$B:$B,D2,'Tier Category Mapping'!$D:$D,"Yes")>0,"Yes","")) | E25: =IF(VLOOKUP($A25,'Control Groups'!$A:$D,3,FALSE)="Tier 0 – Universal","Yes",IF(COUNTIFS('Tier Category Mapping'!$A:$A,VLOOKUP($A25,'Control Groups'!$A:$D,3,FALSE),'Tier Category Mapping'!$B:$B,E2,'Tier Category Mapping'!$D:$D,"Yes")>0,"Yes","")) | F25: =IF(VLOOKUP($A25,'Control Groups'!$A:$D,3,FALSE)="Tier 0 – Universal","Yes",IF(COUNTIFS('Tier Category Mapping'!$A:$A,VLOOKUP($A25,'Control Groups'!$A:$D,3,FALSE),'Tier Category Mapping'!$B:$B,F2,'Tier Category Mapping'!$D:$D,"Yes")>0,"Yes","")) | G25: =IF(VLOOKUP($A25,'Control Groups'!$A:$D,3,FALSE)="Tier 0 – Universal","Yes",IF(COUNTIFS('Tier Category Mapping'!$A:$A,VLOOKUP($A25,'Control Groups'!$A:$D,3,FALSE),'Tier Category Mapping'!$B:$B,G2,'Tier Category Mapping'!$D:$D,"Yes")>0,"Yes","")) | H25: =IF(VLOOKUP($A25,'Control Groups'!$A:$D,3,FALSE)="Tier 0 – Universal","Yes",IF(COUNTIFS('Tier Category Mapping'!$A:$A,VLOOKUP($A25,'Control Groups'!$A:$D,3,FALSE),'Tier Category Mapping'!$B:$B,H2,'Tier Category Mapping'!$D:$D,"Yes")>0,"Yes","")) | I25: =IF(VLOOKUP($A25,'Control Groups'!$A:$D,3,FALSE)="Tier 0 – Universal","Yes",IF(COUNTIFS('Tier Category Mapping'!$A:$A,VLOOKUP($A25,'Control Groups'!$A:$D,3,FALSE),'Tier Category Mapping'!$B:$B,I2,'Tier Category Mapping'!$D:$D,"Yes")>0,"Yes","")) | J25: =IF(VLOOKUP($A25,'Control Groups'!$A:$D,3,FALSE)="Tier 0 – Universal","Yes",IF(COUNTIFS('Tier Category Mapping'!$A:$A,VLOOKUP($A25,'Control Groups'!$A:$D,3,FALSE),'Tier Category Mapping'!$B:$B,J2,'Tier Category Mapping'!$D:$D,"Yes")>0,"Yes","")) | ... W25: =IF(VLOOKUP($A25,'Control Groups'!$A:$D,3,FALSE)="Tier 0 – Universal","Yes",IF(COUNTIFS('Tier Category Mapping'!$A:$A,VLOOKUP($A25,'Control Groups'!$A:$D,3,FALSE),'Tier Category Mapping'!$B:$B,W2,'Tier Category Mapping'!$D:$D,"Yes")>0,"Yes",""))
A26: SOP-07 | B26: Regular patching performed | C26: =IF(VLOOKUP($A26,'Control Groups'!$A:$D,3,FALSE)="Tier 0 – Universal","Yes",IF(COUNTIFS('Tier Category Mapping'!$A:$A,VLOOKUP($A26,'Control Groups'!$A:$D,3,FALSE),'Tier Category Mapping'!$B:$B,C2,'Tier Category Mapping'!$D:$D,"Yes")>0,"Yes","")) | D26: =IF(VLOOKUP($A26,'Control Groups'!$A:$D,3,FALSE)="Tier 0 – Universal","Yes",IF(COUNTIFS('Tier Category Mapping'!$A:$A,VLOOKUP($A26,'Control Groups'!$A:$D,3,FALSE),'Tier Category Mapping'!$B:$B,D2,'Tier Category Mapping'!$D:$D,"Yes")>0,"Yes","")) | E26: =IF(VLOOKUP($A26,'Control Groups'!$A:$D,3,FALSE)="Tier 0 – Universal","Yes",IF(COUNTIFS('Tier Category Mapping'!$A:$A,VLOOKUP($A26,'Control Groups'!$A:$D,3,FALSE),'Tier Category Mapping'!$B:$B,E2,'Tier Category Mapping'!$D:$D,"Yes")>0,"Yes","")) | F26: =IF(VLOOKUP($A26,'Control Groups'!$A:$D,3,FALSE)="Tier 0 – Universal","Yes",IF(COUNTIFS('Tier Category Mapping'!$A:$A,VLOOKUP($A26,'Control Groups'!$A:$D,3,FALSE),'Tier Category Mapping'!$B:$B,F2,'Tier Category Mapping'!$D:$D,"Yes")>0,"Yes","")) | G26: =IF(VLOOKUP($A26,'Control Groups'!$A:$D,3,FALSE)="Tier 0 – Universal","Yes",IF(COUNTIFS('Tier Category Mapping'!$A:$A,VLOOKUP($A26,'Control Groups'!$A:$D,3,FALSE),'Tier Category Mapping'!$B:$B,G2,'Tier Category Mapping'!$D:$D,"Yes")>0,"Yes","")) | H26: =IF(VLOOKUP($A26,'Control Groups'!$A:$D,3,FALSE)="Tier 0 – Universal","Yes",IF(COUNTIFS('Tier Category Mapping'!$A:$A,VLOOKUP($A26,'Control Groups'!$A:$D,3,FALSE),'Tier Category Mapping'!$B:$B,H2,'Tier Category Mapping'!$D:$D,"Yes")>0,"Yes","")) | I26: =IF(VLOOKUP($A26,'Control Groups'!$A:$D,3,FALSE)="Tier 0 – Universal","Yes",IF(COUNTIFS('Tier Category Mapping'!$A:$A,VLOOKUP($A26,'Control Groups'!$A:$D,3,FALSE),'Tier Category Mapping'!$B:$B,I2,'Tier Category Mapping'!$D:$D,"Yes")>0,"Yes","")) | J26: =IF(VLOOKUP($A26,'Control Groups'!$A:$D,3,FALSE)="Tier 0 – Universal","Yes",IF(COUNTIFS('Tier Category Mapping'!$A:$A,VLOOKUP($A26,'Control Groups'!$A:$D,3,FALSE),'Tier Category Mapping'!$B:$B,J2,'Tier Category Mapping'!$D:$D,"Yes")>0,"Yes","")) | ... W26: =IF(VLOOKUP($A26,'Control Groups'!$A:$D,3,FALSE)="Tier 0 – Universal","Yes",IF(COUNTIFS('Tier Category Mapping'!$A:$A,VLOOKUP($A26,'Control Groups'!$A:$D,3,FALSE),'Tier Category Mapping'!$B:$B,W2,'Tier Category Mapping'!$D:$D,"Yes")>0,"Yes",""))
